cannot reshape array of size 100352 into shape (7,2048)
cannot reshape array of size 100352 into shape (7,2048)
cannot reshape array of size 100352 into shape (7,2048)
cannot reshape array of size 100352 into shape (7,2048)
cannot reshape array of size 100352 into shape (7,2048)
cannot reshape array of size 100352 into shape (7,2048)
cannot reshape array of size 100352 into shape (7,2048)
cannot reshape array of size 100352 into shape (7,2048)
cannot reshape array of size 100352 into shape (7,2048)
cannot reshape array of size 100352 into shape (7,2048)
cannot reshape array of size 100352 into shape (7,2048)
cannot reshape array of size 100352 into shape (7,2048)
cannot reshape array of size 100352 into shape (7,2048)
cannot reshape array of size 100352 into shape (7,2048)
cannot reshape array of size 100352 into shape (7,2048)
cannot reshape array of size 100352 into shape (7,2048)
cannot reshape array of size 100352 into shape (7,2048)
cannot reshape array of size 100352 into shape (7,2048)
cannot reshape array of size 100352 into shape (7,2048)
cannot reshape array of size 100352 into shape (7,2048)
cannot reshape array of size 100352 into shape (7,2048)
cannot reshape array of size 100352 into shape (7,2048)
cannot reshape array of size 100352 into shape (7,2048)
cannot reshape array of size 100352 into shape (7,2048)
cannot reshape array of size 100352 into shape (7,2048)
cannot reshape array of size 100352 into shape (7,2048)
Graph execution error:

Detected at node 'resnet50/conv1_pad/Pad' defined at (most recent call last):
    File "/usr/lib/python3.7/runpy.py", line 193, in _run_module_as_main
      "__main__", mod_spec)
    File "/usr/lib/python3.7/runpy.py", line 85, in _run_code
      exec(code, run_globals)
    File "/usr/local/lib/python3.7/dist-packages/ipykernel_launcher.py", line 16, in <module>
      app.launch_new_instance()
    File "/usr/local/lib/python3.7/dist-packages/traitlets/config/application.py", line 846, in launch_instance
      app.start()
    File "/usr/local/lib/python3.7/dist-packages/ipykernel/kernelapp.py", line 612, in start
      self.io_loop.start()
    File "/usr/local/lib/python3.7/dist-packages/tornado/platform/asyncio.py", line 149, in start
      self.asyncio_loop.run_forever()
    File "/usr/lib/python3.7/asyncio/base_events.py", line 541, in run_forever
      self._run_once()
    File "/usr/lib/python3.7/asyncio/base_events.py", line 1786, in _run_once
      handle._run()
    File "/usr/lib/python3.7/asyncio/events.py", line 88, in _run
      self._context.run(self._callback, *self._args)
    File "/usr/local/lib/python3.7/dist-packages/tornado/ioloop.py", line 690, in <lambda>
      lambda f: self._run_callback(functools.partial(callback, future))
    File "/usr/local/lib/python3.7/dist-packages/tornado/ioloop.py", line 743, in _run_callback
      ret = callback()
    File "/usr/local/lib/python3.7/dist-packages/tornado/gen.py", line 787, in inner
      self.run()
    File "/usr/local/lib/python3.7/dist-packages/tornado/gen.py", line 748, in run
      yielded = self.gen.send(value)
    File "/usr/local/lib/python3.7/dist-packages/ipykernel/kernelbase.py", line 365, in process_one
      yield gen.maybe_future(dispatch(*args))
    File "/usr/local/lib/python3.7/dist-packages/tornado/gen.py", line 209, in wrapper
      yielded = next(result)
    File "/usr/local/lib/python3.7/dist-packages/ipykernel/kernelbase.py", line 268, in dispatch_shell
      yield gen.maybe_future(handler(stream, idents, msg))
    File "/usr/local/lib/python3.7/dist-packages/tornado/gen.py", line 209, in wrapper
      yielded = next(result)
    File "/usr/local/lib/python3.7/dist-packages/ipykernel/kernelbase.py", line 545, in execute_request
      user_expressions, allow_stdin,
    File "/usr/local/lib/python3.7/dist-packages/tornado/gen.py", line 209, in wrapper
      yielded = next(result)
    File "/usr/local/lib/python3.7/dist-packages/ipykernel/ipkernel.py", line 306, in do_execute
      res = shell.run_cell(code, store_history=store_history, silent=silent)
    File "/usr/local/lib/python3.7/dist-packages/ipykernel/zmqshell.py", line 536, in run_cell
      return super(ZMQInteractiveShell, self).run_cell(*args, **kwargs)
    File "/usr/local/lib/python3.7/dist-packages/IPython/core/interactiveshell.py", line 2855, in run_cell
      raw_cell, store_history, silent, shell_futures)
    File "/usr/local/lib/python3.7/dist-packages/IPython/core/interactiveshell.py", line 2881, in _run_cell
      return runner(coro)
    File "/usr/local/lib/python3.7/dist-packages/IPython/core/async_helpers.py", line 68, in _pseudo_sync_runner
      coro.send(None)
    File "/usr/local/lib/python3.7/dist-packages/IPython/core/interactiveshell.py", line 3058, in run_cell_async
      interactivity=interactivity, compiler=compiler, result=result)
    File "/usr/local/lib/python3.7/dist-packages/IPython/core/interactiveshell.py", line 3249, in run_ast_nodes
      if (await self.run_code(code, result,  async_=asy)):
    File "/usr/local/lib/python3.7/dist-packages/IPython/core/interactiveshell.py", line 3326, in run_code
      exec(code_obj, self.user_global_ns, self.user_ns)
    File "<ipython-input-7-5a99192cc838>", line 27, in <module>
      x_transformed = get_feature(feature_extractor, x)
    File "/content/drive/MyDrive/GoBiz/core/helper.py", line 19, in get_feature
      feature_vector = clf.predict(img)
    File "/usr/local/lib/python3.7/dist-packages/keras/utils/traceback_utils.py", line 64, in error_handler
      return fn(*args, **kwargs)
    File "/usr/local/lib/python3.7/dist-packages/keras/engine/training.py", line 2033, in predict
      tmp_batch_outputs = self.predict_function(iterator)
    File "/usr/local/lib/python3.7/dist-packages/keras/engine/training.py", line 1845, in predict_function
      return step_function(self, iterator)
    File "/usr/local/lib/python3.7/dist-packages/keras/engine/training.py", line 1834, in step_function
      outputs = model.distribute_strategy.run(run_step, args=(data,))
    File "/usr/local/lib/python3.7/dist-packages/keras/engine/training.py", line 1823, in run_step
      outputs = model.predict_step(data)
    File "/usr/local/lib/python3.7/dist-packages/keras/engine/training.py", line 1791, in predict_step
      return self(x, training=False)
    File "/usr/local/lib/python3.7/dist-packages/keras/utils/traceback_utils.py", line 64, in error_handler
      return fn(*args, **kwargs)
    File "/usr/local/lib/python3.7/dist-packages/keras/engine/training.py", line 490, in __call__
      return super().__call__(*args, **kwargs)
    File "/usr/local/lib/python3.7/dist-packages/keras/utils/traceback_utils.py", line 64, in error_handler
      return fn(*args, **kwargs)
    File "/usr/local/lib/python3.7/dist-packages/keras/engine/base_layer.py", line 1014, in __call__
      outputs = call_fn(inputs, *args, **kwargs)
    File "/usr/local/lib/python3.7/dist-packages/keras/utils/traceback_utils.py", line 92, in error_handler
      return fn(*args, **kwargs)
    File "/usr/local/lib/python3.7/dist-packages/keras/engine/functional.py", line 459, in call
      inputs, training=training, mask=mask)
    File "/usr/local/lib/python3.7/dist-packages/keras/engine/functional.py", line 596, in _run_internal_graph
      outputs = node.layer(*args, **kwargs)
    File "/usr/local/lib/python3.7/dist-packages/keras/utils/traceback_utils.py", line 64, in error_handler
      return fn(*args, **kwargs)
    File "/usr/local/lib/python3.7/dist-packages/keras/engine/base_layer.py", line 1014, in __call__
      outputs = call_fn(inputs, *args, **kwargs)
    File "/usr/local/lib/python3.7/dist-packages/keras/utils/traceback_utils.py", line 92, in error_handler
      return fn(*args, **kwargs)
    File "/usr/local/lib/python3.7/dist-packages/keras/layers/reshaping/zero_padding2d.py", line 144, in call
      inputs, padding=self.padding, data_format=self.data_format)
    File "/usr/local/lib/python3.7/dist-packages/keras/backend.py", line 3770, in spatial_2d_padding
      return tf.compat.v1.pad(x, pattern)
Node: 'resnet50/conv1_pad/Pad'
The first dimension of paddings must be the rank of inputs[4,2] [32]
	 [[{{node resnet50/conv1_pad/Pad}}]] [Op:__inference_predict_function_6597]
Graph execution error:

Detected at node 'resnet50/conv1_pad/Pad' defined at (most recent call last):
    File "/usr/lib/python3.7/runpy.py", line 193, in _run_module_as_main
      "__main__", mod_spec)
    File "/usr/lib/python3.7/runpy.py", line 85, in _run_code
      exec(code, run_globals)
    File "/usr/local/lib/python3.7/dist-packages/ipykernel_launcher.py", line 16, in <module>
      app.launch_new_instance()
    File "/usr/local/lib/python3.7/dist-packages/traitlets/config/application.py", line 846, in launch_instance
      app.start()
    File "/usr/local/lib/python3.7/dist-packages/ipykernel/kernelapp.py", line 612, in start
      self.io_loop.start()
    File "/usr/local/lib/python3.7/dist-packages/tornado/platform/asyncio.py", line 149, in start
      self.asyncio_loop.run_forever()
    File "/usr/lib/python3.7/asyncio/base_events.py", line 541, in run_forever
      self._run_once()
    File "/usr/lib/python3.7/asyncio/base_events.py", line 1786, in _run_once
      handle._run()
    File "/usr/lib/python3.7/asyncio/events.py", line 88, in _run
      self._context.run(self._callback, *self._args)
    File "/usr/local/lib/python3.7/dist-packages/tornado/ioloop.py", line 690, in <lambda>
      lambda f: self._run_callback(functools.partial(callback, future))
    File "/usr/local/lib/python3.7/dist-packages/tornado/ioloop.py", line 743, in _run_callback
      ret = callback()
    File "/usr/local/lib/python3.7/dist-packages/tornado/gen.py", line 787, in inner
      self.run()
    File "/usr/local/lib/python3.7/dist-packages/tornado/gen.py", line 748, in run
      yielded = self.gen.send(value)
    File "/usr/local/lib/python3.7/dist-packages/ipykernel/kernelbase.py", line 365, in process_one
      yield gen.maybe_future(dispatch(*args))
    File "/usr/local/lib/python3.7/dist-packages/tornado/gen.py", line 209, in wrapper
      yielded = next(result)
    File "/usr/local/lib/python3.7/dist-packages/ipykernel/kernelbase.py", line 268, in dispatch_shell
      yield gen.maybe_future(handler(stream, idents, msg))
    File "/usr/local/lib/python3.7/dist-packages/tornado/gen.py", line 209, in wrapper
      yielded = next(result)
    File "/usr/local/lib/python3.7/dist-packages/ipykernel/kernelbase.py", line 545, in execute_request
      user_expressions, allow_stdin,
    File "/usr/local/lib/python3.7/dist-packages/tornado/gen.py", line 209, in wrapper
      yielded = next(result)
    File "/usr/local/lib/python3.7/dist-packages/ipykernel/ipkernel.py", line 306, in do_execute
      res = shell.run_cell(code, store_history=store_history, silent=silent)
    File "/usr/local/lib/python3.7/dist-packages/ipykernel/zmqshell.py", line 536, in run_cell
      return super(ZMQInteractiveShell, self).run_cell(*args, **kwargs)
    File "/usr/local/lib/python3.7/dist-packages/IPython/core/interactiveshell.py", line 2855, in run_cell
      raw_cell, store_history, silent, shell_futures)
    File "/usr/local/lib/python3.7/dist-packages/IPython/core/interactiveshell.py", line 2881, in _run_cell
      return runner(coro)
    File "/usr/local/lib/python3.7/dist-packages/IPython/core/async_helpers.py", line 68, in _pseudo_sync_runner
      coro.send(None)
    File "/usr/local/lib/python3.7/dist-packages/IPython/core/interactiveshell.py", line 3058, in run_cell_async
      interactivity=interactivity, compiler=compiler, result=result)
    File "/usr/local/lib/python3.7/dist-packages/IPython/core/interactiveshell.py", line 3249, in run_ast_nodes
      if (await self.run_code(code, result,  async_=asy)):
    File "/usr/local/lib/python3.7/dist-packages/IPython/core/interactiveshell.py", line 3326, in run_code
      exec(code_obj, self.user_global_ns, self.user_ns)
    File "<ipython-input-7-5a99192cc838>", line 27, in <module>
      x_transformed = get_feature(feature_extractor, x)
    File "/content/drive/MyDrive/GoBiz/core/helper.py", line 19, in get_feature
      feature_vector = clf.predict(img)
    File "/usr/local/lib/python3.7/dist-packages/keras/utils/traceback_utils.py", line 64, in error_handler
      return fn(*args, **kwargs)
    File "/usr/local/lib/python3.7/dist-packages/keras/engine/training.py", line 2033, in predict
      tmp_batch_outputs = self.predict_function(iterator)
    File "/usr/local/lib/python3.7/dist-packages/keras/engine/training.py", line 1845, in predict_function
      return step_function(self, iterator)
    File "/usr/local/lib/python3.7/dist-packages/keras/engine/training.py", line 1834, in step_function
      outputs = model.distribute_strategy.run(run_step, args=(data,))
    File "/usr/local/lib/python3.7/dist-packages/keras/engine/training.py", line 1823, in run_step
      outputs = model.predict_step(data)
    File "/usr/local/lib/python3.7/dist-packages/keras/engine/training.py", line 1791, in predict_step
      return self(x, training=False)
    File "/usr/local/lib/python3.7/dist-packages/keras/utils/traceback_utils.py", line 64, in error_handler
      return fn(*args, **kwargs)
    File "/usr/local/lib/python3.7/dist-packages/keras/engine/training.py", line 490, in __call__
      return super().__call__(*args, **kwargs)
    File "/usr/local/lib/python3.7/dist-packages/keras/utils/traceback_utils.py", line 64, in error_handler
      return fn(*args, **kwargs)
    File "/usr/local/lib/python3.7/dist-packages/keras/engine/base_layer.py", line 1014, in __call__
      outputs = call_fn(inputs, *args, **kwargs)
    File "/usr/local/lib/python3.7/dist-packages/keras/utils/traceback_utils.py", line 92, in error_handler
      return fn(*args, **kwargs)
    File "/usr/local/lib/python3.7/dist-packages/keras/engine/functional.py", line 459, in call
      inputs, training=training, mask=mask)
    File "/usr/local/lib/python3.7/dist-packages/keras/engine/functional.py", line 596, in _run_internal_graph
      outputs = node.layer(*args, **kwargs)
    File "/usr/local/lib/python3.7/dist-packages/keras/utils/traceback_utils.py", line 64, in error_handler
      return fn(*args, **kwargs)
    File "/usr/local/lib/python3.7/dist-packages/keras/engine/base_layer.py", line 1014, in __call__
      outputs = call_fn(inputs, *args, **kwargs)
    File "/usr/local/lib/python3.7/dist-packages/keras/utils/traceback_utils.py", line 92, in error_handler
      return fn(*args, **kwargs)
    File "/usr/local/lib/python3.7/dist-packages/keras/layers/reshaping/zero_padding2d.py", line 144, in call
      inputs, padding=self.padding, data_format=self.data_format)
    File "/usr/local/lib/python3.7/dist-packages/keras/backend.py", line 3770, in spatial_2d_padding
      return tf.compat.v1.pad(x, pattern)
Node: 'resnet50/conv1_pad/Pad'
The first dimension of paddings must be the rank of inputs[4,2] [32]
	 [[{{node resnet50/conv1_pad/Pad}}]] [Op:__inference_predict_function_6597]
Graph execution error:

Detected at node 'resnet50/conv1_pad/Pad' defined at (most recent call last):
    File "/usr/lib/python3.7/runpy.py", line 193, in _run_module_as_main
      "__main__", mod_spec)
    File "/usr/lib/python3.7/runpy.py", line 85, in _run_code
      exec(code, run_globals)
    File "/usr/local/lib/python3.7/dist-packages/ipykernel_launcher.py", line 16, in <module>
      app.launch_new_instance()
    File "/usr/local/lib/python3.7/dist-packages/traitlets/config/application.py", line 846, in launch_instance
      app.start()
    File "/usr/local/lib/python3.7/dist-packages/ipykernel/kernelapp.py", line 612, in start
      self.io_loop.start()
    File "/usr/local/lib/python3.7/dist-packages/tornado/platform/asyncio.py", line 149, in start
      self.asyncio_loop.run_forever()
    File "/usr/lib/python3.7/asyncio/base_events.py", line 541, in run_forever
      self._run_once()
    File "/usr/lib/python3.7/asyncio/base_events.py", line 1786, in _run_once
      handle._run()
    File "/usr/lib/python3.7/asyncio/events.py", line 88, in _run
      self._context.run(self._callback, *self._args)
    File "/usr/local/lib/python3.7/dist-packages/tornado/ioloop.py", line 690, in <lambda>
      lambda f: self._run_callback(functools.partial(callback, future))
    File "/usr/local/lib/python3.7/dist-packages/tornado/ioloop.py", line 743, in _run_callback
      ret = callback()
    File "/usr/local/lib/python3.7/dist-packages/tornado/gen.py", line 787, in inner
      self.run()
    File "/usr/local/lib/python3.7/dist-packages/tornado/gen.py", line 748, in run
      yielded = self.gen.send(value)
    File "/usr/local/lib/python3.7/dist-packages/ipykernel/kernelbase.py", line 365, in process_one
      yield gen.maybe_future(dispatch(*args))
    File "/usr/local/lib/python3.7/dist-packages/tornado/gen.py", line 209, in wrapper
      yielded = next(result)
    File "/usr/local/lib/python3.7/dist-packages/ipykernel/kernelbase.py", line 268, in dispatch_shell
      yield gen.maybe_future(handler(stream, idents, msg))
    File "/usr/local/lib/python3.7/dist-packages/tornado/gen.py", line 209, in wrapper
      yielded = next(result)
    File "/usr/local/lib/python3.7/dist-packages/ipykernel/kernelbase.py", line 545, in execute_request
      user_expressions, allow_stdin,
    File "/usr/local/lib/python3.7/dist-packages/tornado/gen.py", line 209, in wrapper
      yielded = next(result)
    File "/usr/local/lib/python3.7/dist-packages/ipykernel/ipkernel.py", line 306, in do_execute
      res = shell.run_cell(code, store_history=store_history, silent=silent)
    File "/usr/local/lib/python3.7/dist-packages/ipykernel/zmqshell.py", line 536, in run_cell
      return super(ZMQInteractiveShell, self).run_cell(*args, **kwargs)
    File "/usr/local/lib/python3.7/dist-packages/IPython/core/interactiveshell.py", line 2855, in run_cell
      raw_cell, store_history, silent, shell_futures)
    File "/usr/local/lib/python3.7/dist-packages/IPython/core/interactiveshell.py", line 2881, in _run_cell
      return runner(coro)
    File "/usr/local/lib/python3.7/dist-packages/IPython/core/async_helpers.py", line 68, in _pseudo_sync_runner
      coro.send(None)
    File "/usr/local/lib/python3.7/dist-packages/IPython/core/interactiveshell.py", line 3058, in run_cell_async
      interactivity=interactivity, compiler=compiler, result=result)
    File "/usr/local/lib/python3.7/dist-packages/IPython/core/interactiveshell.py", line 3249, in run_ast_nodes
      if (await self.run_code(code, result,  async_=asy)):
    File "/usr/local/lib/python3.7/dist-packages/IPython/core/interactiveshell.py", line 3326, in run_code
      exec(code_obj, self.user_global_ns, self.user_ns)
    File "<ipython-input-7-5a99192cc838>", line 27, in <module>
      x_transformed = get_feature(feature_extractor, x)
    File "/content/drive/MyDrive/GoBiz/core/helper.py", line 19, in get_feature
      feature_vector = clf.predict(img)
    File "/usr/local/lib/python3.7/dist-packages/keras/utils/traceback_utils.py", line 64, in error_handler
      return fn(*args, **kwargs)
    File "/usr/local/lib/python3.7/dist-packages/keras/engine/training.py", line 2033, in predict
      tmp_batch_outputs = self.predict_function(iterator)
    File "/usr/local/lib/python3.7/dist-packages/keras/engine/training.py", line 1845, in predict_function
      return step_function(self, iterator)
    File "/usr/local/lib/python3.7/dist-packages/keras/engine/training.py", line 1834, in step_function
      outputs = model.distribute_strategy.run(run_step, args=(data,))
    File "/usr/local/lib/python3.7/dist-packages/keras/engine/training.py", line 1823, in run_step
      outputs = model.predict_step(data)
    File "/usr/local/lib/python3.7/dist-packages/keras/engine/training.py", line 1791, in predict_step
      return self(x, training=False)
    File "/usr/local/lib/python3.7/dist-packages/keras/utils/traceback_utils.py", line 64, in error_handler
      return fn(*args, **kwargs)
    File "/usr/local/lib/python3.7/dist-packages/keras/engine/training.py", line 490, in __call__
      return super().__call__(*args, **kwargs)
    File "/usr/local/lib/python3.7/dist-packages/keras/utils/traceback_utils.py", line 64, in error_handler
      return fn(*args, **kwargs)
    File "/usr/local/lib/python3.7/dist-packages/keras/engine/base_layer.py", line 1014, in __call__
      outputs = call_fn(inputs, *args, **kwargs)
    File "/usr/local/lib/python3.7/dist-packages/keras/utils/traceback_utils.py", line 92, in error_handler
      return fn(*args, **kwargs)
    File "/usr/local/lib/python3.7/dist-packages/keras/engine/functional.py", line 459, in call
      inputs, training=training, mask=mask)
    File "/usr/local/lib/python3.7/dist-packages/keras/engine/functional.py", line 596, in _run_internal_graph
      outputs = node.layer(*args, **kwargs)
    File "/usr/local/lib/python3.7/dist-packages/keras/utils/traceback_utils.py", line 64, in error_handler
      return fn(*args, **kwargs)
    File "/usr/local/lib/python3.7/dist-packages/keras/engine/base_layer.py", line 1014, in __call__
      outputs = call_fn(inputs, *args, **kwargs)
    File "/usr/local/lib/python3.7/dist-packages/keras/utils/traceback_utils.py", line 92, in error_handler
      return fn(*args, **kwargs)
    File "/usr/local/lib/python3.7/dist-packages/keras/layers/reshaping/zero_padding2d.py", line 144, in call
      inputs, padding=self.padding, data_format=self.data_format)
    File "/usr/local/lib/python3.7/dist-packages/keras/backend.py", line 3770, in spatial_2d_padding
      return tf.compat.v1.pad(x, pattern)
Node: 'resnet50/conv1_pad/Pad'
The first dimension of paddings must be the rank of inputs[4,2] [32]
	 [[{{node resnet50/conv1_pad/Pad}}]] [Op:__inference_predict_function_6597]
Graph execution error:

Detected at node 'resnet50/conv1_pad/Pad' defined at (most recent call last):
    File "/usr/lib/python3.7/runpy.py", line 193, in _run_module_as_main
      "__main__", mod_spec)
    File "/usr/lib/python3.7/runpy.py", line 85, in _run_code
      exec(code, run_globals)
    File "/usr/local/lib/python3.7/dist-packages/ipykernel_launcher.py", line 16, in <module>
      app.launch_new_instance()
    File "/usr/local/lib/python3.7/dist-packages/traitlets/config/application.py", line 846, in launch_instance
      app.start()
    File "/usr/local/lib/python3.7/dist-packages/ipykernel/kernelapp.py", line 612, in start
      self.io_loop.start()
    File "/usr/local/lib/python3.7/dist-packages/tornado/platform/asyncio.py", line 149, in start
      self.asyncio_loop.run_forever()
    File "/usr/lib/python3.7/asyncio/base_events.py", line 541, in run_forever
      self._run_once()
    File "/usr/lib/python3.7/asyncio/base_events.py", line 1786, in _run_once
      handle._run()
    File "/usr/lib/python3.7/asyncio/events.py", line 88, in _run
      self._context.run(self._callback, *self._args)
    File "/usr/local/lib/python3.7/dist-packages/tornado/ioloop.py", line 690, in <lambda>
      lambda f: self._run_callback(functools.partial(callback, future))
    File "/usr/local/lib/python3.7/dist-packages/tornado/ioloop.py", line 743, in _run_callback
      ret = callback()
    File "/usr/local/lib/python3.7/dist-packages/tornado/gen.py", line 787, in inner
      self.run()
    File "/usr/local/lib/python3.7/dist-packages/tornado/gen.py", line 748, in run
      yielded = self.gen.send(value)
    File "/usr/local/lib/python3.7/dist-packages/ipykernel/kernelbase.py", line 365, in process_one
      yield gen.maybe_future(dispatch(*args))
    File "/usr/local/lib/python3.7/dist-packages/tornado/gen.py", line 209, in wrapper
      yielded = next(result)
    File "/usr/local/lib/python3.7/dist-packages/ipykernel/kernelbase.py", line 268, in dispatch_shell
      yield gen.maybe_future(handler(stream, idents, msg))
    File "/usr/local/lib/python3.7/dist-packages/tornado/gen.py", line 209, in wrapper
      yielded = next(result)
    File "/usr/local/lib/python3.7/dist-packages/ipykernel/kernelbase.py", line 545, in execute_request
      user_expressions, allow_stdin,
    File "/usr/local/lib/python3.7/dist-packages/tornado/gen.py", line 209, in wrapper
      yielded = next(result)
    File "/usr/local/lib/python3.7/dist-packages/ipykernel/ipkernel.py", line 306, in do_execute
      res = shell.run_cell(code, store_history=store_history, silent=silent)
    File "/usr/local/lib/python3.7/dist-packages/ipykernel/zmqshell.py", line 536, in run_cell
      return super(ZMQInteractiveShell, self).run_cell(*args, **kwargs)
    File "/usr/local/lib/python3.7/dist-packages/IPython/core/interactiveshell.py", line 2855, in run_cell
      raw_cell, store_history, silent, shell_futures)
    File "/usr/local/lib/python3.7/dist-packages/IPython/core/interactiveshell.py", line 2881, in _run_cell
      return runner(coro)
    File "/usr/local/lib/python3.7/dist-packages/IPython/core/async_helpers.py", line 68, in _pseudo_sync_runner
      coro.send(None)
    File "/usr/local/lib/python3.7/dist-packages/IPython/core/interactiveshell.py", line 3058, in run_cell_async
      interactivity=interactivity, compiler=compiler, result=result)
    File "/usr/local/lib/python3.7/dist-packages/IPython/core/interactiveshell.py", line 3249, in run_ast_nodes
      if (await self.run_code(code, result,  async_=asy)):
    File "/usr/local/lib/python3.7/dist-packages/IPython/core/interactiveshell.py", line 3326, in run_code
      exec(code_obj, self.user_global_ns, self.user_ns)
    File "<ipython-input-7-5a99192cc838>", line 27, in <module>
      x_transformed = get_feature(feature_extractor, x)
    File "/content/drive/MyDrive/GoBiz/core/helper.py", line 19, in get_feature
      feature_vector = clf.predict(img)
    File "/usr/local/lib/python3.7/dist-packages/keras/utils/traceback_utils.py", line 64, in error_handler
      return fn(*args, **kwargs)
    File "/usr/local/lib/python3.7/dist-packages/keras/engine/training.py", line 2033, in predict
      tmp_batch_outputs = self.predict_function(iterator)
    File "/usr/local/lib/python3.7/dist-packages/keras/engine/training.py", line 1845, in predict_function
      return step_function(self, iterator)
    File "/usr/local/lib/python3.7/dist-packages/keras/engine/training.py", line 1834, in step_function
      outputs = model.distribute_strategy.run(run_step, args=(data,))
    File "/usr/local/lib/python3.7/dist-packages/keras/engine/training.py", line 1823, in run_step
      outputs = model.predict_step(data)
    File "/usr/local/lib/python3.7/dist-packages/keras/engine/training.py", line 1791, in predict_step
      return self(x, training=False)
    File "/usr/local/lib/python3.7/dist-packages/keras/utils/traceback_utils.py", line 64, in error_handler
      return fn(*args, **kwargs)
    File "/usr/local/lib/python3.7/dist-packages/keras/engine/training.py", line 490, in __call__
      return super().__call__(*args, **kwargs)
    File "/usr/local/lib/python3.7/dist-packages/keras/utils/traceback_utils.py", line 64, in error_handler
      return fn(*args, **kwargs)
    File "/usr/local/lib/python3.7/dist-packages/keras/engine/base_layer.py", line 1014, in __call__
      outputs = call_fn(inputs, *args, **kwargs)
    File "/usr/local/lib/python3.7/dist-packages/keras/utils/traceback_utils.py", line 92, in error_handler
      return fn(*args, **kwargs)
    File "/usr/local/lib/python3.7/dist-packages/keras/engine/functional.py", line 459, in call
      inputs, training=training, mask=mask)
    File "/usr/local/lib/python3.7/dist-packages/keras/engine/functional.py", line 596, in _run_internal_graph
      outputs = node.layer(*args, **kwargs)
    File "/usr/local/lib/python3.7/dist-packages/keras/utils/traceback_utils.py", line 64, in error_handler
      return fn(*args, **kwargs)
    File "/usr/local/lib/python3.7/dist-packages/keras/engine/base_layer.py", line 1014, in __call__
      outputs = call_fn(inputs, *args, **kwargs)
    File "/usr/local/lib/python3.7/dist-packages/keras/utils/traceback_utils.py", line 92, in error_handler
      return fn(*args, **kwargs)
    File "/usr/local/lib/python3.7/dist-packages/keras/layers/reshaping/zero_padding2d.py", line 144, in call
      inputs, padding=self.padding, data_format=self.data_format)
    File "/usr/local/lib/python3.7/dist-packages/keras/backend.py", line 3770, in spatial_2d_padding
      return tf.compat.v1.pad(x, pattern)
Node: 'resnet50/conv1_pad/Pad'
The first dimension of paddings must be the rank of inputs[4,2] [32]
	 [[{{node resnet50/conv1_pad/Pad}}]] [Op:__inference_predict_function_6597]
Graph execution error:

Detected at node 'resnet50/conv1_pad/Pad' defined at (most recent call last):
    File "/usr/lib/python3.7/runpy.py", line 193, in _run_module_as_main
      "__main__", mod_spec)
    File "/usr/lib/python3.7/runpy.py", line 85, in _run_code
      exec(code, run_globals)
    File "/usr/local/lib/python3.7/dist-packages/ipykernel_launcher.py", line 16, in <module>
      app.launch_new_instance()
    File "/usr/local/lib/python3.7/dist-packages/traitlets/config/application.py", line 846, in launch_instance
      app.start()
    File "/usr/local/lib/python3.7/dist-packages/ipykernel/kernelapp.py", line 612, in start
      self.io_loop.start()
    File "/usr/local/lib/python3.7/dist-packages/tornado/platform/asyncio.py", line 149, in start
      self.asyncio_loop.run_forever()
    File "/usr/lib/python3.7/asyncio/base_events.py", line 541, in run_forever
      self._run_once()
    File "/usr/lib/python3.7/asyncio/base_events.py", line 1786, in _run_once
      handle._run()
    File "/usr/lib/python3.7/asyncio/events.py", line 88, in _run
      self._context.run(self._callback, *self._args)
    File "/usr/local/lib/python3.7/dist-packages/tornado/ioloop.py", line 690, in <lambda>
      lambda f: self._run_callback(functools.partial(callback, future))
    File "/usr/local/lib/python3.7/dist-packages/tornado/ioloop.py", line 743, in _run_callback
      ret = callback()
    File "/usr/local/lib/python3.7/dist-packages/tornado/gen.py", line 787, in inner
      self.run()
    File "/usr/local/lib/python3.7/dist-packages/tornado/gen.py", line 748, in run
      yielded = self.gen.send(value)
    File "/usr/local/lib/python3.7/dist-packages/ipykernel/kernelbase.py", line 365, in process_one
      yield gen.maybe_future(dispatch(*args))
    File "/usr/local/lib/python3.7/dist-packages/tornado/gen.py", line 209, in wrapper
      yielded = next(result)
    File "/usr/local/lib/python3.7/dist-packages/ipykernel/kernelbase.py", line 268, in dispatch_shell
      yield gen.maybe_future(handler(stream, idents, msg))
    File "/usr/local/lib/python3.7/dist-packages/tornado/gen.py", line 209, in wrapper
      yielded = next(result)
    File "/usr/local/lib/python3.7/dist-packages/ipykernel/kernelbase.py", line 545, in execute_request
      user_expressions, allow_stdin,
    File "/usr/local/lib/python3.7/dist-packages/tornado/gen.py", line 209, in wrapper
      yielded = next(result)
    File "/usr/local/lib/python3.7/dist-packages/ipykernel/ipkernel.py", line 306, in do_execute
      res = shell.run_cell(code, store_history=store_history, silent=silent)
    File "/usr/local/lib/python3.7/dist-packages/ipykernel/zmqshell.py", line 536, in run_cell
      return super(ZMQInteractiveShell, self).run_cell(*args, **kwargs)
    File "/usr/local/lib/python3.7/dist-packages/IPython/core/interactiveshell.py", line 2855, in run_cell
      raw_cell, store_history, silent, shell_futures)
    File "/usr/local/lib/python3.7/dist-packages/IPython/core/interactiveshell.py", line 2881, in _run_cell
      return runner(coro)
    File "/usr/local/lib/python3.7/dist-packages/IPython/core/async_helpers.py", line 68, in _pseudo_sync_runner
      coro.send(None)
    File "/usr/local/lib/python3.7/dist-packages/IPython/core/interactiveshell.py", line 3058, in run_cell_async
      interactivity=interactivity, compiler=compiler, result=result)
    File "/usr/local/lib/python3.7/dist-packages/IPython/core/interactiveshell.py", line 3249, in run_ast_nodes
      if (await self.run_code(code, result,  async_=asy)):
    File "/usr/local/lib/python3.7/dist-packages/IPython/core/interactiveshell.py", line 3326, in run_code
      exec(code_obj, self.user_global_ns, self.user_ns)
    File "<ipython-input-7-5a99192cc838>", line 27, in <module>
      x_transformed = get_feature(feature_extractor, x)
    File "/content/drive/MyDrive/GoBiz/core/helper.py", line 19, in get_feature
      feature_vector = clf.predict(img)
    File "/usr/local/lib/python3.7/dist-packages/keras/utils/traceback_utils.py", line 64, in error_handler
      return fn(*args, **kwargs)
    File "/usr/local/lib/python3.7/dist-packages/keras/engine/training.py", line 2033, in predict
      tmp_batch_outputs = self.predict_function(iterator)
    File "/usr/local/lib/python3.7/dist-packages/keras/engine/training.py", line 1845, in predict_function
      return step_function(self, iterator)
    File "/usr/local/lib/python3.7/dist-packages/keras/engine/training.py", line 1834, in step_function
      outputs = model.distribute_strategy.run(run_step, args=(data,))
    File "/usr/local/lib/python3.7/dist-packages/keras/engine/training.py", line 1823, in run_step
      outputs = model.predict_step(data)
    File "/usr/local/lib/python3.7/dist-packages/keras/engine/training.py", line 1791, in predict_step
      return self(x, training=False)
    File "/usr/local/lib/python3.7/dist-packages/keras/utils/traceback_utils.py", line 64, in error_handler
      return fn(*args, **kwargs)
    File "/usr/local/lib/python3.7/dist-packages/keras/engine/training.py", line 490, in __call__
      return super().__call__(*args, **kwargs)
    File "/usr/local/lib/python3.7/dist-packages/keras/utils/traceback_utils.py", line 64, in error_handler
      return fn(*args, **kwargs)
    File "/usr/local/lib/python3.7/dist-packages/keras/engine/base_layer.py", line 1014, in __call__
      outputs = call_fn(inputs, *args, **kwargs)
    File "/usr/local/lib/python3.7/dist-packages/keras/utils/traceback_utils.py", line 92, in error_handler
      return fn(*args, **kwargs)
    File "/usr/local/lib/python3.7/dist-packages/keras/engine/functional.py", line 459, in call
      inputs, training=training, mask=mask)
    File "/usr/local/lib/python3.7/dist-packages/keras/engine/functional.py", line 596, in _run_internal_graph
      outputs = node.layer(*args, **kwargs)
    File "/usr/local/lib/python3.7/dist-packages/keras/utils/traceback_utils.py", line 64, in error_handler
      return fn(*args, **kwargs)
    File "/usr/local/lib/python3.7/dist-packages/keras/engine/base_layer.py", line 1014, in __call__
      outputs = call_fn(inputs, *args, **kwargs)
    File "/usr/local/lib/python3.7/dist-packages/keras/utils/traceback_utils.py", line 92, in error_handler
      return fn(*args, **kwargs)
    File "/usr/local/lib/python3.7/dist-packages/keras/layers/reshaping/zero_padding2d.py", line 144, in call
      inputs, padding=self.padding, data_format=self.data_format)
    File "/usr/local/lib/python3.7/dist-packages/keras/backend.py", line 3770, in spatial_2d_padding
      return tf.compat.v1.pad(x, pattern)
Node: 'resnet50/conv1_pad/Pad'
The first dimension of paddings must be the rank of inputs[4,2] [32]
	 [[{{node resnet50/conv1_pad/Pad}}]] [Op:__inference_predict_function_6597]
Graph execution error:

Detected at node 'resnet50/conv1_pad/Pad' defined at (most recent call last):
    File "/usr/lib/python3.7/runpy.py", line 193, in _run_module_as_main
      "__main__", mod_spec)
    File "/usr/lib/python3.7/runpy.py", line 85, in _run_code
      exec(code, run_globals)
    File "/usr/local/lib/python3.7/dist-packages/ipykernel_launcher.py", line 16, in <module>
      app.launch_new_instance()
    File "/usr/local/lib/python3.7/dist-packages/traitlets/config/application.py", line 846, in launch_instance
      app.start()
    File "/usr/local/lib/python3.7/dist-packages/ipykernel/kernelapp.py", line 612, in start
      self.io_loop.start()
    File "/usr/local/lib/python3.7/dist-packages/tornado/platform/asyncio.py", line 149, in start
      self.asyncio_loop.run_forever()
    File "/usr/lib/python3.7/asyncio/base_events.py", line 541, in run_forever
      self._run_once()
    File "/usr/lib/python3.7/asyncio/base_events.py", line 1786, in _run_once
      handle._run()
    File "/usr/lib/python3.7/asyncio/events.py", line 88, in _run
      self._context.run(self._callback, *self._args)
    File "/usr/local/lib/python3.7/dist-packages/tornado/ioloop.py", line 690, in <lambda>
      lambda f: self._run_callback(functools.partial(callback, future))
    File "/usr/local/lib/python3.7/dist-packages/tornado/ioloop.py", line 743, in _run_callback
      ret = callback()
    File "/usr/local/lib/python3.7/dist-packages/tornado/gen.py", line 787, in inner
      self.run()
    File "/usr/local/lib/python3.7/dist-packages/tornado/gen.py", line 748, in run
      yielded = self.gen.send(value)
    File "/usr/local/lib/python3.7/dist-packages/ipykernel/kernelbase.py", line 365, in process_one
      yield gen.maybe_future(dispatch(*args))
    File "/usr/local/lib/python3.7/dist-packages/tornado/gen.py", line 209, in wrapper
      yielded = next(result)
    File "/usr/local/lib/python3.7/dist-packages/ipykernel/kernelbase.py", line 268, in dispatch_shell
      yield gen.maybe_future(handler(stream, idents, msg))
    File "/usr/local/lib/python3.7/dist-packages/tornado/gen.py", line 209, in wrapper
      yielded = next(result)
    File "/usr/local/lib/python3.7/dist-packages/ipykernel/kernelbase.py", line 545, in execute_request
      user_expressions, allow_stdin,
    File "/usr/local/lib/python3.7/dist-packages/tornado/gen.py", line 209, in wrapper
      yielded = next(result)
    File "/usr/local/lib/python3.7/dist-packages/ipykernel/ipkernel.py", line 306, in do_execute
      res = shell.run_cell(code, store_history=store_history, silent=silent)
    File "/usr/local/lib/python3.7/dist-packages/ipykernel/zmqshell.py", line 536, in run_cell
      return super(ZMQInteractiveShell, self).run_cell(*args, **kwargs)
    File "/usr/local/lib/python3.7/dist-packages/IPython/core/interactiveshell.py", line 2855, in run_cell
      raw_cell, store_history, silent, shell_futures)
    File "/usr/local/lib/python3.7/dist-packages/IPython/core/interactiveshell.py", line 2881, in _run_cell
      return runner(coro)
    File "/usr/local/lib/python3.7/dist-packages/IPython/core/async_helpers.py", line 68, in _pseudo_sync_runner
      coro.send(None)
    File "/usr/local/lib/python3.7/dist-packages/IPython/core/interactiveshell.py", line 3058, in run_cell_async
      interactivity=interactivity, compiler=compiler, result=result)
    File "/usr/local/lib/python3.7/dist-packages/IPython/core/interactiveshell.py", line 3249, in run_ast_nodes
      if (await self.run_code(code, result,  async_=asy)):
    File "/usr/local/lib/python3.7/dist-packages/IPython/core/interactiveshell.py", line 3326, in run_code
      exec(code_obj, self.user_global_ns, self.user_ns)
    File "<ipython-input-7-5a99192cc838>", line 27, in <module>
      x_transformed = get_feature(feature_extractor, x)
    File "/content/drive/MyDrive/GoBiz/core/helper.py", line 19, in get_feature
      feature_vector = clf.predict(img)
    File "/usr/local/lib/python3.7/dist-packages/keras/utils/traceback_utils.py", line 64, in error_handler
      return fn(*args, **kwargs)
    File "/usr/local/lib/python3.7/dist-packages/keras/engine/training.py", line 2033, in predict
      tmp_batch_outputs = self.predict_function(iterator)
    File "/usr/local/lib/python3.7/dist-packages/keras/engine/training.py", line 1845, in predict_function
      return step_function(self, iterator)
    File "/usr/local/lib/python3.7/dist-packages/keras/engine/training.py", line 1834, in step_function
      outputs = model.distribute_strategy.run(run_step, args=(data,))
    File "/usr/local/lib/python3.7/dist-packages/keras/engine/training.py", line 1823, in run_step
      outputs = model.predict_step(data)
    File "/usr/local/lib/python3.7/dist-packages/keras/engine/training.py", line 1791, in predict_step
      return self(x, training=False)
    File "/usr/local/lib/python3.7/dist-packages/keras/utils/traceback_utils.py", line 64, in error_handler
      return fn(*args, **kwargs)
    File "/usr/local/lib/python3.7/dist-packages/keras/engine/training.py", line 490, in __call__
      return super().__call__(*args, **kwargs)
    File "/usr/local/lib/python3.7/dist-packages/keras/utils/traceback_utils.py", line 64, in error_handler
      return fn(*args, **kwargs)
    File "/usr/local/lib/python3.7/dist-packages/keras/engine/base_layer.py", line 1014, in __call__
      outputs = call_fn(inputs, *args, **kwargs)
    File "/usr/local/lib/python3.7/dist-packages/keras/utils/traceback_utils.py", line 92, in error_handler
      return fn(*args, **kwargs)
    File "/usr/local/lib/python3.7/dist-packages/keras/engine/functional.py", line 459, in call
      inputs, training=training, mask=mask)
    File "/usr/local/lib/python3.7/dist-packages/keras/engine/functional.py", line 596, in _run_internal_graph
      outputs = node.layer(*args, **kwargs)
    File "/usr/local/lib/python3.7/dist-packages/keras/utils/traceback_utils.py", line 64, in error_handler
      return fn(*args, **kwargs)
    File "/usr/local/lib/python3.7/dist-packages/keras/engine/base_layer.py", line 1014, in __call__
      outputs = call_fn(inputs, *args, **kwargs)
    File "/usr/local/lib/python3.7/dist-packages/keras/utils/traceback_utils.py", line 92, in error_handler
      return fn(*args, **kwargs)
    File "/usr/local/lib/python3.7/dist-packages/keras/layers/reshaping/zero_padding2d.py", line 144, in call
      inputs, padding=self.padding, data_format=self.data_format)
    File "/usr/local/lib/python3.7/dist-packages/keras/backend.py", line 3770, in spatial_2d_padding
      return tf.compat.v1.pad(x, pattern)
Node: 'resnet50/conv1_pad/Pad'
The first dimension of paddings must be the rank of inputs[4,2] [32]
	 [[{{node resnet50/conv1_pad/Pad}}]] [Op:__inference_predict_function_6597]
Graph execution error:

Detected at node 'resnet50/conv1_pad/Pad' defined at (most recent call last):
    File "/usr/lib/python3.7/runpy.py", line 193, in _run_module_as_main
      "__main__", mod_spec)
    File "/usr/lib/python3.7/runpy.py", line 85, in _run_code
      exec(code, run_globals)
    File "/usr/local/lib/python3.7/dist-packages/ipykernel_launcher.py", line 16, in <module>
      app.launch_new_instance()
    File "/usr/local/lib/python3.7/dist-packages/traitlets/config/application.py", line 846, in launch_instance
      app.start()
    File "/usr/local/lib/python3.7/dist-packages/ipykernel/kernelapp.py", line 612, in start
      self.io_loop.start()
    File "/usr/local/lib/python3.7/dist-packages/tornado/platform/asyncio.py", line 149, in start
      self.asyncio_loop.run_forever()
    File "/usr/lib/python3.7/asyncio/base_events.py", line 541, in run_forever
      self._run_once()
    File "/usr/lib/python3.7/asyncio/base_events.py", line 1786, in _run_once
      handle._run()
    File "/usr/lib/python3.7/asyncio/events.py", line 88, in _run
      self._context.run(self._callback, *self._args)
    File "/usr/local/lib/python3.7/dist-packages/tornado/ioloop.py", line 690, in <lambda>
      lambda f: self._run_callback(functools.partial(callback, future))
    File "/usr/local/lib/python3.7/dist-packages/tornado/ioloop.py", line 743, in _run_callback
      ret = callback()
    File "/usr/local/lib/python3.7/dist-packages/tornado/gen.py", line 787, in inner
      self.run()
    File "/usr/local/lib/python3.7/dist-packages/tornado/gen.py", line 748, in run
      yielded = self.gen.send(value)
    File "/usr/local/lib/python3.7/dist-packages/ipykernel/kernelbase.py", line 365, in process_one
      yield gen.maybe_future(dispatch(*args))
    File "/usr/local/lib/python3.7/dist-packages/tornado/gen.py", line 209, in wrapper
      yielded = next(result)
    File "/usr/local/lib/python3.7/dist-packages/ipykernel/kernelbase.py", line 268, in dispatch_shell
      yield gen.maybe_future(handler(stream, idents, msg))
    File "/usr/local/lib/python3.7/dist-packages/tornado/gen.py", line 209, in wrapper
      yielded = next(result)
    File "/usr/local/lib/python3.7/dist-packages/ipykernel/kernelbase.py", line 545, in execute_request
      user_expressions, allow_stdin,
    File "/usr/local/lib/python3.7/dist-packages/tornado/gen.py", line 209, in wrapper
      yielded = next(result)
    File "/usr/local/lib/python3.7/dist-packages/ipykernel/ipkernel.py", line 306, in do_execute
      res = shell.run_cell(code, store_history=store_history, silent=silent)
    File "/usr/local/lib/python3.7/dist-packages/ipykernel/zmqshell.py", line 536, in run_cell
      return super(ZMQInteractiveShell, self).run_cell(*args, **kwargs)
    File "/usr/local/lib/python3.7/dist-packages/IPython/core/interactiveshell.py", line 2855, in run_cell
      raw_cell, store_history, silent, shell_futures)
    File "/usr/local/lib/python3.7/dist-packages/IPython/core/interactiveshell.py", line 2881, in _run_cell
      return runner(coro)
    File "/usr/local/lib/python3.7/dist-packages/IPython/core/async_helpers.py", line 68, in _pseudo_sync_runner
      coro.send(None)
    File "/usr/local/lib/python3.7/dist-packages/IPython/core/interactiveshell.py", line 3058, in run_cell_async
      interactivity=interactivity, compiler=compiler, result=result)
    File "/usr/local/lib/python3.7/dist-packages/IPython/core/interactiveshell.py", line 3249, in run_ast_nodes
      if (await self.run_code(code, result,  async_=asy)):
    File "/usr/local/lib/python3.7/dist-packages/IPython/core/interactiveshell.py", line 3326, in run_code
      exec(code_obj, self.user_global_ns, self.user_ns)
    File "<ipython-input-7-5a99192cc838>", line 27, in <module>
      x_transformed = get_feature(feature_extractor, x)
    File "/content/drive/MyDrive/GoBiz/core/helper.py", line 19, in get_feature
      feature_vector = clf.predict(img)
    File "/usr/local/lib/python3.7/dist-packages/keras/utils/traceback_utils.py", line 64, in error_handler
      return fn(*args, **kwargs)
    File "/usr/local/lib/python3.7/dist-packages/keras/engine/training.py", line 2033, in predict
      tmp_batch_outputs = self.predict_function(iterator)
    File "/usr/local/lib/python3.7/dist-packages/keras/engine/training.py", line 1845, in predict_function
      return step_function(self, iterator)
    File "/usr/local/lib/python3.7/dist-packages/keras/engine/training.py", line 1834, in step_function
      outputs = model.distribute_strategy.run(run_step, args=(data,))
    File "/usr/local/lib/python3.7/dist-packages/keras/engine/training.py", line 1823, in run_step
      outputs = model.predict_step(data)
    File "/usr/local/lib/python3.7/dist-packages/keras/engine/training.py", line 1791, in predict_step
      return self(x, training=False)
    File "/usr/local/lib/python3.7/dist-packages/keras/utils/traceback_utils.py", line 64, in error_handler
      return fn(*args, **kwargs)
    File "/usr/local/lib/python3.7/dist-packages/keras/engine/training.py", line 490, in __call__
      return super().__call__(*args, **kwargs)
    File "/usr/local/lib/python3.7/dist-packages/keras/utils/traceback_utils.py", line 64, in error_handler
      return fn(*args, **kwargs)
    File "/usr/local/lib/python3.7/dist-packages/keras/engine/base_layer.py", line 1014, in __call__
      outputs = call_fn(inputs, *args, **kwargs)
    File "/usr/local/lib/python3.7/dist-packages/keras/utils/traceback_utils.py", line 92, in error_handler
      return fn(*args, **kwargs)
    File "/usr/local/lib/python3.7/dist-packages/keras/engine/functional.py", line 459, in call
      inputs, training=training, mask=mask)
    File "/usr/local/lib/python3.7/dist-packages/keras/engine/functional.py", line 596, in _run_internal_graph
      outputs = node.layer(*args, **kwargs)
    File "/usr/local/lib/python3.7/dist-packages/keras/utils/traceback_utils.py", line 64, in error_handler
      return fn(*args, **kwargs)
    File "/usr/local/lib/python3.7/dist-packages/keras/engine/base_layer.py", line 1014, in __call__
      outputs = call_fn(inputs, *args, **kwargs)
    File "/usr/local/lib/python3.7/dist-packages/keras/utils/traceback_utils.py", line 92, in error_handler
      return fn(*args, **kwargs)
    File "/usr/local/lib/python3.7/dist-packages/keras/layers/reshaping/zero_padding2d.py", line 144, in call
      inputs, padding=self.padding, data_format=self.data_format)
    File "/usr/local/lib/python3.7/dist-packages/keras/backend.py", line 3770, in spatial_2d_padding
      return tf.compat.v1.pad(x, pattern)
Node: 'resnet50/conv1_pad/Pad'
The first dimension of paddings must be the rank of inputs[4,2] [32]
	 [[{{node resnet50/conv1_pad/Pad}}]] [Op:__inference_predict_function_6597]
Graph execution error:

Detected at node 'resnet50/conv1_pad/Pad' defined at (most recent call last):
    File "/usr/lib/python3.7/runpy.py", line 193, in _run_module_as_main
      "__main__", mod_spec)
    File "/usr/lib/python3.7/runpy.py", line 85, in _run_code
      exec(code, run_globals)
    File "/usr/local/lib/python3.7/dist-packages/ipykernel_launcher.py", line 16, in <module>
      app.launch_new_instance()
    File "/usr/local/lib/python3.7/dist-packages/traitlets/config/application.py", line 846, in launch_instance
      app.start()
    File "/usr/local/lib/python3.7/dist-packages/ipykernel/kernelapp.py", line 612, in start
      self.io_loop.start()
    File "/usr/local/lib/python3.7/dist-packages/tornado/platform/asyncio.py", line 149, in start
      self.asyncio_loop.run_forever()
    File "/usr/lib/python3.7/asyncio/base_events.py", line 541, in run_forever
      self._run_once()
    File "/usr/lib/python3.7/asyncio/base_events.py", line 1786, in _run_once
      handle._run()
    File "/usr/lib/python3.7/asyncio/events.py", line 88, in _run
      self._context.run(self._callback, *self._args)
    File "/usr/local/lib/python3.7/dist-packages/tornado/ioloop.py", line 690, in <lambda>
      lambda f: self._run_callback(functools.partial(callback, future))
    File "/usr/local/lib/python3.7/dist-packages/tornado/ioloop.py", line 743, in _run_callback
      ret = callback()
    File "/usr/local/lib/python3.7/dist-packages/tornado/gen.py", line 787, in inner
      self.run()
    File "/usr/local/lib/python3.7/dist-packages/tornado/gen.py", line 748, in run
      yielded = self.gen.send(value)
    File "/usr/local/lib/python3.7/dist-packages/ipykernel/kernelbase.py", line 365, in process_one
      yield gen.maybe_future(dispatch(*args))
    File "/usr/local/lib/python3.7/dist-packages/tornado/gen.py", line 209, in wrapper
      yielded = next(result)
    File "/usr/local/lib/python3.7/dist-packages/ipykernel/kernelbase.py", line 268, in dispatch_shell
      yield gen.maybe_future(handler(stream, idents, msg))
    File "/usr/local/lib/python3.7/dist-packages/tornado/gen.py", line 209, in wrapper
      yielded = next(result)
    File "/usr/local/lib/python3.7/dist-packages/ipykernel/kernelbase.py", line 545, in execute_request
      user_expressions, allow_stdin,
    File "/usr/local/lib/python3.7/dist-packages/tornado/gen.py", line 209, in wrapper
      yielded = next(result)
    File "/usr/local/lib/python3.7/dist-packages/ipykernel/ipkernel.py", line 306, in do_execute
      res = shell.run_cell(code, store_history=store_history, silent=silent)
    File "/usr/local/lib/python3.7/dist-packages/ipykernel/zmqshell.py", line 536, in run_cell
      return super(ZMQInteractiveShell, self).run_cell(*args, **kwargs)
    File "/usr/local/lib/python3.7/dist-packages/IPython/core/interactiveshell.py", line 2855, in run_cell
      raw_cell, store_history, silent, shell_futures)
    File "/usr/local/lib/python3.7/dist-packages/IPython/core/interactiveshell.py", line 2881, in _run_cell
      return runner(coro)
    File "/usr/local/lib/python3.7/dist-packages/IPython/core/async_helpers.py", line 68, in _pseudo_sync_runner
      coro.send(None)
    File "/usr/local/lib/python3.7/dist-packages/IPython/core/interactiveshell.py", line 3058, in run_cell_async
      interactivity=interactivity, compiler=compiler, result=result)
    File "/usr/local/lib/python3.7/dist-packages/IPython/core/interactiveshell.py", line 3249, in run_ast_nodes
      if (await self.run_code(code, result,  async_=asy)):
    File "/usr/local/lib/python3.7/dist-packages/IPython/core/interactiveshell.py", line 3326, in run_code
      exec(code_obj, self.user_global_ns, self.user_ns)
    File "<ipython-input-7-5a99192cc838>", line 27, in <module>
      x_transformed = get_feature(feature_extractor, x)
    File "/content/drive/MyDrive/GoBiz/core/helper.py", line 19, in get_feature
      feature_vector = clf.predict(img)
    File "/usr/local/lib/python3.7/dist-packages/keras/utils/traceback_utils.py", line 64, in error_handler
      return fn(*args, **kwargs)
    File "/usr/local/lib/python3.7/dist-packages/keras/engine/training.py", line 2033, in predict
      tmp_batch_outputs = self.predict_function(iterator)
    File "/usr/local/lib/python3.7/dist-packages/keras/engine/training.py", line 1845, in predict_function
      return step_function(self, iterator)
    File "/usr/local/lib/python3.7/dist-packages/keras/engine/training.py", line 1834, in step_function
      outputs = model.distribute_strategy.run(run_step, args=(data,))
    File "/usr/local/lib/python3.7/dist-packages/keras/engine/training.py", line 1823, in run_step
      outputs = model.predict_step(data)
    File "/usr/local/lib/python3.7/dist-packages/keras/engine/training.py", line 1791, in predict_step
      return self(x, training=False)
    File "/usr/local/lib/python3.7/dist-packages/keras/utils/traceback_utils.py", line 64, in error_handler
      return fn(*args, **kwargs)
    File "/usr/local/lib/python3.7/dist-packages/keras/engine/training.py", line 490, in __call__
      return super().__call__(*args, **kwargs)
    File "/usr/local/lib/python3.7/dist-packages/keras/utils/traceback_utils.py", line 64, in error_handler
      return fn(*args, **kwargs)
    File "/usr/local/lib/python3.7/dist-packages/keras/engine/base_layer.py", line 1014, in __call__
      outputs = call_fn(inputs, *args, **kwargs)
    File "/usr/local/lib/python3.7/dist-packages/keras/utils/traceback_utils.py", line 92, in error_handler
      return fn(*args, **kwargs)
    File "/usr/local/lib/python3.7/dist-packages/keras/engine/functional.py", line 459, in call
      inputs, training=training, mask=mask)
    File "/usr/local/lib/python3.7/dist-packages/keras/engine/functional.py", line 596, in _run_internal_graph
      outputs = node.layer(*args, **kwargs)
    File "/usr/local/lib/python3.7/dist-packages/keras/utils/traceback_utils.py", line 64, in error_handler
      return fn(*args, **kwargs)
    File "/usr/local/lib/python3.7/dist-packages/keras/engine/base_layer.py", line 1014, in __call__
      outputs = call_fn(inputs, *args, **kwargs)
    File "/usr/local/lib/python3.7/dist-packages/keras/utils/traceback_utils.py", line 92, in error_handler
      return fn(*args, **kwargs)
    File "/usr/local/lib/python3.7/dist-packages/keras/layers/reshaping/zero_padding2d.py", line 144, in call
      inputs, padding=self.padding, data_format=self.data_format)
    File "/usr/local/lib/python3.7/dist-packages/keras/backend.py", line 3770, in spatial_2d_padding
      return tf.compat.v1.pad(x, pattern)
Node: 'resnet50/conv1_pad/Pad'
The first dimension of paddings must be the rank of inputs[4,2] [32]
	 [[{{node resnet50/conv1_pad/Pad}}]] [Op:__inference_predict_function_6597]
Graph execution error:

Detected at node 'resnet50/conv1_pad/Pad' defined at (most recent call last):
    File "/usr/lib/python3.7/runpy.py", line 193, in _run_module_as_main
      "__main__", mod_spec)
    File "/usr/lib/python3.7/runpy.py", line 85, in _run_code
      exec(code, run_globals)
    File "/usr/local/lib/python3.7/dist-packages/ipykernel_launcher.py", line 16, in <module>
      app.launch_new_instance()
    File "/usr/local/lib/python3.7/dist-packages/traitlets/config/application.py", line 846, in launch_instance
      app.start()
    File "/usr/local/lib/python3.7/dist-packages/ipykernel/kernelapp.py", line 612, in start
      self.io_loop.start()
    File "/usr/local/lib/python3.7/dist-packages/tornado/platform/asyncio.py", line 149, in start
      self.asyncio_loop.run_forever()
    File "/usr/lib/python3.7/asyncio/base_events.py", line 541, in run_forever
      self._run_once()
    File "/usr/lib/python3.7/asyncio/base_events.py", line 1786, in _run_once
      handle._run()
    File "/usr/lib/python3.7/asyncio/events.py", line 88, in _run
      self._context.run(self._callback, *self._args)
    File "/usr/local/lib/python3.7/dist-packages/tornado/ioloop.py", line 690, in <lambda>
      lambda f: self._run_callback(functools.partial(callback, future))
    File "/usr/local/lib/python3.7/dist-packages/tornado/ioloop.py", line 743, in _run_callback
      ret = callback()
    File "/usr/local/lib/python3.7/dist-packages/tornado/gen.py", line 787, in inner
      self.run()
    File "/usr/local/lib/python3.7/dist-packages/tornado/gen.py", line 748, in run
      yielded = self.gen.send(value)
    File "/usr/local/lib/python3.7/dist-packages/ipykernel/kernelbase.py", line 365, in process_one
      yield gen.maybe_future(dispatch(*args))
    File "/usr/local/lib/python3.7/dist-packages/tornado/gen.py", line 209, in wrapper
      yielded = next(result)
    File "/usr/local/lib/python3.7/dist-packages/ipykernel/kernelbase.py", line 268, in dispatch_shell
      yield gen.maybe_future(handler(stream, idents, msg))
    File "/usr/local/lib/python3.7/dist-packages/tornado/gen.py", line 209, in wrapper
      yielded = next(result)
    File "/usr/local/lib/python3.7/dist-packages/ipykernel/kernelbase.py", line 545, in execute_request
      user_expressions, allow_stdin,
    File "/usr/local/lib/python3.7/dist-packages/tornado/gen.py", line 209, in wrapper
      yielded = next(result)
    File "/usr/local/lib/python3.7/dist-packages/ipykernel/ipkernel.py", line 306, in do_execute
      res = shell.run_cell(code, store_history=store_history, silent=silent)
    File "/usr/local/lib/python3.7/dist-packages/ipykernel/zmqshell.py", line 536, in run_cell
      return super(ZMQInteractiveShell, self).run_cell(*args, **kwargs)
    File "/usr/local/lib/python3.7/dist-packages/IPython/core/interactiveshell.py", line 2855, in run_cell
      raw_cell, store_history, silent, shell_futures)
    File "/usr/local/lib/python3.7/dist-packages/IPython/core/interactiveshell.py", line 2881, in _run_cell
      return runner(coro)
    File "/usr/local/lib/python3.7/dist-packages/IPython/core/async_helpers.py", line 68, in _pseudo_sync_runner
      coro.send(None)
    File "/usr/local/lib/python3.7/dist-packages/IPython/core/interactiveshell.py", line 3058, in run_cell_async
      interactivity=interactivity, compiler=compiler, result=result)
    File "/usr/local/lib/python3.7/dist-packages/IPython/core/interactiveshell.py", line 3249, in run_ast_nodes
      if (await self.run_code(code, result,  async_=asy)):
    File "/usr/local/lib/python3.7/dist-packages/IPython/core/interactiveshell.py", line 3326, in run_code
      exec(code_obj, self.user_global_ns, self.user_ns)
    File "<ipython-input-7-5a99192cc838>", line 27, in <module>
      x_transformed = get_feature(feature_extractor, x)
    File "/content/drive/MyDrive/GoBiz/core/helper.py", line 19, in get_feature
      feature_vector = clf.predict(img)
    File "/usr/local/lib/python3.7/dist-packages/keras/utils/traceback_utils.py", line 64, in error_handler
      return fn(*args, **kwargs)
    File "/usr/local/lib/python3.7/dist-packages/keras/engine/training.py", line 2033, in predict
      tmp_batch_outputs = self.predict_function(iterator)
    File "/usr/local/lib/python3.7/dist-packages/keras/engine/training.py", line 1845, in predict_function
      return step_function(self, iterator)
    File "/usr/local/lib/python3.7/dist-packages/keras/engine/training.py", line 1834, in step_function
      outputs = model.distribute_strategy.run(run_step, args=(data,))
    File "/usr/local/lib/python3.7/dist-packages/keras/engine/training.py", line 1823, in run_step
      outputs = model.predict_step(data)
    File "/usr/local/lib/python3.7/dist-packages/keras/engine/training.py", line 1791, in predict_step
      return self(x, training=False)
    File "/usr/local/lib/python3.7/dist-packages/keras/utils/traceback_utils.py", line 64, in error_handler
      return fn(*args, **kwargs)
    File "/usr/local/lib/python3.7/dist-packages/keras/engine/training.py", line 490, in __call__
      return super().__call__(*args, **kwargs)
    File "/usr/local/lib/python3.7/dist-packages/keras/utils/traceback_utils.py", line 64, in error_handler
      return fn(*args, **kwargs)
    File "/usr/local/lib/python3.7/dist-packages/keras/engine/base_layer.py", line 1014, in __call__
      outputs = call_fn(inputs, *args, **kwargs)
    File "/usr/local/lib/python3.7/dist-packages/keras/utils/traceback_utils.py", line 92, in error_handler
      return fn(*args, **kwargs)
    File "/usr/local/lib/python3.7/dist-packages/keras/engine/functional.py", line 459, in call
      inputs, training=training, mask=mask)
    File "/usr/local/lib/python3.7/dist-packages/keras/engine/functional.py", line 596, in _run_internal_graph
      outputs = node.layer(*args, **kwargs)
    File "/usr/local/lib/python3.7/dist-packages/keras/utils/traceback_utils.py", line 64, in error_handler
      return fn(*args, **kwargs)
    File "/usr/local/lib/python3.7/dist-packages/keras/engine/base_layer.py", line 1014, in __call__
      outputs = call_fn(inputs, *args, **kwargs)
    File "/usr/local/lib/python3.7/dist-packages/keras/utils/traceback_utils.py", line 92, in error_handler
      return fn(*args, **kwargs)
    File "/usr/local/lib/python3.7/dist-packages/keras/layers/reshaping/zero_padding2d.py", line 144, in call
      inputs, padding=self.padding, data_format=self.data_format)
    File "/usr/local/lib/python3.7/dist-packages/keras/backend.py", line 3770, in spatial_2d_padding
      return tf.compat.v1.pad(x, pattern)
Node: 'resnet50/conv1_pad/Pad'
The first dimension of paddings must be the rank of inputs[4,2] [32]
	 [[{{node resnet50/conv1_pad/Pad}}]] [Op:__inference_predict_function_6597]
Graph execution error:

Detected at node 'resnet50/conv1_pad/Pad' defined at (most recent call last):
    File "/usr/lib/python3.7/runpy.py", line 193, in _run_module_as_main
      "__main__", mod_spec)
    File "/usr/lib/python3.7/runpy.py", line 85, in _run_code
      exec(code, run_globals)
    File "/usr/local/lib/python3.7/dist-packages/ipykernel_launcher.py", line 16, in <module>
      app.launch_new_instance()
    File "/usr/local/lib/python3.7/dist-packages/traitlets/config/application.py", line 846, in launch_instance
      app.start()
    File "/usr/local/lib/python3.7/dist-packages/ipykernel/kernelapp.py", line 612, in start
      self.io_loop.start()
    File "/usr/local/lib/python3.7/dist-packages/tornado/platform/asyncio.py", line 149, in start
      self.asyncio_loop.run_forever()
    File "/usr/lib/python3.7/asyncio/base_events.py", line 541, in run_forever
      self._run_once()
    File "/usr/lib/python3.7/asyncio/base_events.py", line 1786, in _run_once
      handle._run()
    File "/usr/lib/python3.7/asyncio/events.py", line 88, in _run
      self._context.run(self._callback, *self._args)
    File "/usr/local/lib/python3.7/dist-packages/tornado/ioloop.py", line 690, in <lambda>
      lambda f: self._run_callback(functools.partial(callback, future))
    File "/usr/local/lib/python3.7/dist-packages/tornado/ioloop.py", line 743, in _run_callback
      ret = callback()
    File "/usr/local/lib/python3.7/dist-packages/tornado/gen.py", line 787, in inner
      self.run()
    File "/usr/local/lib/python3.7/dist-packages/tornado/gen.py", line 748, in run
      yielded = self.gen.send(value)
    File "/usr/local/lib/python3.7/dist-packages/ipykernel/kernelbase.py", line 365, in process_one
      yield gen.maybe_future(dispatch(*args))
    File "/usr/local/lib/python3.7/dist-packages/tornado/gen.py", line 209, in wrapper
      yielded = next(result)
    File "/usr/local/lib/python3.7/dist-packages/ipykernel/kernelbase.py", line 268, in dispatch_shell
      yield gen.maybe_future(handler(stream, idents, msg))
    File "/usr/local/lib/python3.7/dist-packages/tornado/gen.py", line 209, in wrapper
      yielded = next(result)
    File "/usr/local/lib/python3.7/dist-packages/ipykernel/kernelbase.py", line 545, in execute_request
      user_expressions, allow_stdin,
    File "/usr/local/lib/python3.7/dist-packages/tornado/gen.py", line 209, in wrapper
      yielded = next(result)
    File "/usr/local/lib/python3.7/dist-packages/ipykernel/ipkernel.py", line 306, in do_execute
      res = shell.run_cell(code, store_history=store_history, silent=silent)
    File "/usr/local/lib/python3.7/dist-packages/ipykernel/zmqshell.py", line 536, in run_cell
      return super(ZMQInteractiveShell, self).run_cell(*args, **kwargs)
    File "/usr/local/lib/python3.7/dist-packages/IPython/core/interactiveshell.py", line 2855, in run_cell
      raw_cell, store_history, silent, shell_futures)
    File "/usr/local/lib/python3.7/dist-packages/IPython/core/interactiveshell.py", line 2881, in _run_cell
      return runner(coro)
    File "/usr/local/lib/python3.7/dist-packages/IPython/core/async_helpers.py", line 68, in _pseudo_sync_runner
      coro.send(None)
    File "/usr/local/lib/python3.7/dist-packages/IPython/core/interactiveshell.py", line 3058, in run_cell_async
      interactivity=interactivity, compiler=compiler, result=result)
    File "/usr/local/lib/python3.7/dist-packages/IPython/core/interactiveshell.py", line 3249, in run_ast_nodes
      if (await self.run_code(code, result,  async_=asy)):
    File "/usr/local/lib/python3.7/dist-packages/IPython/core/interactiveshell.py", line 3326, in run_code
      exec(code_obj, self.user_global_ns, self.user_ns)
    File "<ipython-input-7-5a99192cc838>", line 27, in <module>
      x_transformed = get_feature(feature_extractor, x)
    File "/content/drive/MyDrive/GoBiz/core/helper.py", line 19, in get_feature
      feature_vector = clf.predict(img)
    File "/usr/local/lib/python3.7/dist-packages/keras/utils/traceback_utils.py", line 64, in error_handler
      return fn(*args, **kwargs)
    File "/usr/local/lib/python3.7/dist-packages/keras/engine/training.py", line 2033, in predict
      tmp_batch_outputs = self.predict_function(iterator)
    File "/usr/local/lib/python3.7/dist-packages/keras/engine/training.py", line 1845, in predict_function
      return step_function(self, iterator)
    File "/usr/local/lib/python3.7/dist-packages/keras/engine/training.py", line 1834, in step_function
      outputs = model.distribute_strategy.run(run_step, args=(data,))
    File "/usr/local/lib/python3.7/dist-packages/keras/engine/training.py", line 1823, in run_step
      outputs = model.predict_step(data)
    File "/usr/local/lib/python3.7/dist-packages/keras/engine/training.py", line 1791, in predict_step
      return self(x, training=False)
    File "/usr/local/lib/python3.7/dist-packages/keras/utils/traceback_utils.py", line 64, in error_handler
      return fn(*args, **kwargs)
    File "/usr/local/lib/python3.7/dist-packages/keras/engine/training.py", line 490, in __call__
      return super().__call__(*args, **kwargs)
    File "/usr/local/lib/python3.7/dist-packages/keras/utils/traceback_utils.py", line 64, in error_handler
      return fn(*args, **kwargs)
    File "/usr/local/lib/python3.7/dist-packages/keras/engine/base_layer.py", line 1014, in __call__
      outputs = call_fn(inputs, *args, **kwargs)
    File "/usr/local/lib/python3.7/dist-packages/keras/utils/traceback_utils.py", line 92, in error_handler
      return fn(*args, **kwargs)
    File "/usr/local/lib/python3.7/dist-packages/keras/engine/functional.py", line 459, in call
      inputs, training=training, mask=mask)
    File "/usr/local/lib/python3.7/dist-packages/keras/engine/functional.py", line 596, in _run_internal_graph
      outputs = node.layer(*args, **kwargs)
    File "/usr/local/lib/python3.7/dist-packages/keras/utils/traceback_utils.py", line 64, in error_handler
      return fn(*args, **kwargs)
    File "/usr/local/lib/python3.7/dist-packages/keras/engine/base_layer.py", line 1014, in __call__
      outputs = call_fn(inputs, *args, **kwargs)
    File "/usr/local/lib/python3.7/dist-packages/keras/utils/traceback_utils.py", line 92, in error_handler
      return fn(*args, **kwargs)
    File "/usr/local/lib/python3.7/dist-packages/keras/layers/reshaping/zero_padding2d.py", line 144, in call
      inputs, padding=self.padding, data_format=self.data_format)
    File "/usr/local/lib/python3.7/dist-packages/keras/backend.py", line 3770, in spatial_2d_padding
      return tf.compat.v1.pad(x, pattern)
Node: 'resnet50/conv1_pad/Pad'
The first dimension of paddings must be the rank of inputs[4,2] [32]
	 [[{{node resnet50/conv1_pad/Pad}}]] [Op:__inference_predict_function_6597]
cannot reshape array of size 100352 into shape (7,2048)
cannot reshape array of size 100352 into shape (7,2048)
cannot reshape array of size 100352 into shape (7,2048)
cannot reshape array of size 100352 into shape (7,2048)
cannot reshape array of size 100352 into shape (7,2048)
cannot reshape array of size 100352 into shape (7,2048)
cannot reshape array of size 100352 into shape (7,2048)
cannot reshape array of size 100352 into shape (7,2048)
cannot reshape array of size 100352 into shape (7,2048)
cannot reshape array of size 100352 into shape (7,2048)
cannot reshape array of size 100352 into shape (7,2048)
cannot reshape array of size 100352 into shape (7,2048)
cannot reshape array of size 100352 into shape (7,2048)
cannot reshape array of size 100352 into shape (7,2048)
cannot reshape array of size 100352 into shape (7,2048)
cannot reshape array of size 100352 into shape (7,2048)
cannot reshape array of size 100352 into shape (7,2048)
cannot reshape array of size 100352 into shape (7,2048)
cannot reshape array of size 100352 into shape (7,2048)
cannot reshape array of size 100352 into shape (7,2048)
cannot reshape array of size 100352 into shape (7,2048)
cannot reshape array of size 100352 into shape (7,2048)
cannot reshape array of size 100352 into shape (7,2048)
cannot reshape array of size 100352 into shape (7,2048)
cannot reshape array of size 100352 into shape (7,2048)
cannot reshape array of size 100352 into shape (7,2048)
cannot reshape array of size 100352 into shape (7,2048)
cannot reshape array of size 100352 into shape (7,2048)
cannot reshape array of size 100352 into shape (7,2048)
cannot reshape array of size 100352 into shape (7,2048)
